<robot name="example_robot">
<!--
KR 120 R3100-2
-->
	<link name="base_black_cylinder">
		<visual>
			<origin xyz="0 0 0.125" rpy="0 0 0"/>
			<material name="black">
				<color rgba="0 0 0 1"/>
			</material>
			<geometry>
				<cylinder length="0.25" radius="0.15"/>
			</geometry>
		</visual>
	</link>
	<link name="base_box_on_back">
		<visual>
			<origin xyz="0 -0.05 0.35" rpy="0 0 0"/>
			<material name="orange">
				<color rgba="1 0.35 0.045 1"/>
			</material>
			<geometry>
				<box size="0.2 0.15 0.2" />
			</geometry>
		</visual>
	</link>
	<link name="base_sticking_out_box">
		<visual>
			<origin xyz="-0.035 0.075 0.4" rpy="0 0 0"/>
			<material name="orange"/>
			<geometry>
				<box size="0.13 0.1 0.1" />
			</geometry>
		</visual>
	</link>
	<link name="cylinder_between_0_1">
		<visual>
			<origin xyz="0.035 0.075 0.4" rpy="0 1.57 0"/>
			<material name="orange"/>
			<geometry>
				<cylinder length="0.1" radius="0.05"/>
			</geometry>
		</visual>
	</link>
	<link name="my_link1">
		<visual>
			<origin xyz="0 0 0.3225" rpy="0 0 0"/>
			<material name="orange">
				<color rgba="1 0.35 0.045 1"/>
			</material>
			<geometry>
				<box size="0.12 0.1 1.4" />
			</geometry>
		</visual>
	</link>
	<link name="cylinder_between_1_2">
		<visual>
			<origin xyz="0 0 0.3225" rpy="0 0 0"/>
			<material name="orange">
				<color rgba="1 0.35 0.045 1"/>
			</material>
			<geometry>
				<cylinder length="0.2" radius="0.2"/>
			</geometry>
		</visual>
	</link>	
	<link name="my_link2">
		<visual>
			<origin xyz="0 0 0.3225" rpy="0 0 0"/>
			<material name="orange">
				<color rgba="1 0.35 0.045 1"/>
			</material>
			<geometry>
				<cylinder length="1.4" radius="0.15"/>
			</geometry>
		</visual>
	</link>
	<link name="zwezenie">
		<visual>
			<origin xyz="0 0 0.3225" rpy="0 0 0"/>
			<material name="orange">
				<color rgba="1 0.35 0.045 1"/>
			</material>
			<geometry>
				<cylinder length="0.2" radius="0.1"/>
			</geometry>
		</visual>
	</link>
	<link name="end_part_cylinder_w_poprzek">
		<visual>
			<origin xyz="0 0 0.3225" rpy="0 0 0"/>
			<material name="orange">
				<color rgba="1 0.35 0.045 1"/>
			</material>
			<geometry>
				<cylinder length="0.25" radius="0.1"/>
			</geometry>
		</visual>
	</link>	
	<link name="end_part_cylinder">
		<visual>
			<origin xyz="0 0 0.3225" rpy="0 0 0"/>
			<material name="orange">
				<color rgba="1 0.35 0.045 1"/>
			</material>
			<geometry>
				<cylinder length="0.05" radius="0.2"/>
			</geometry>
		</visual>
	</link>	
<!-- 
black base cylinder
orange box  kawałek wystaje 
can add cylinder between
do tego kolejny box juz jako ramie 
i cylinder do konca
pod koniec wezszyjak to jest zrobione ponizej

link0_passive i link0_x_axis połączone przez q0_x fixed


 -->
	
	
	<link name="link0_passive">
		<visual>
			<material name="blue">
				<color rgba="0 0 .8 1"/>
			</material>
			<geometry>
				<origin xyz="0 0 0" rpy="0 0 0"/>
				<cylinder length="0.0" radius="0.0"/>
			</geometry>
		</visual>
	</link>
	<link name="link0_x_axis">
		<visual>
			<material name="red">
				<color rgba="1 0 0 1"/>
			</material>
			<geometry>
				<origin xyz="0 0 0" rpy="0 0 0"/>
				<cylinder length="0.0" radius="0.0"/>
			</geometry>
		</visual>
	</link>
	<joint name="q0_x" type="fixed">
		<origin xyz="0 0 0" rpy="0 1.571 0"/>
		<parent link="link0_passive"/>
		<child link="link0_x_axis"/>
	</joint>
	<link name="link1"/>
	<link name="link1_x_axis">
		<visual>
			<origin xyz="0 0 0.25" rpy="0 0 0"/>
			<material name="red"/>
			<geometry>
				<cylinder length="0.5" radius="0.05"/>
			</geometry>
		</visual>
	</link>
	<joint name="q1" type="revolute">
		<origin xyz="0 0 0.645" rpy="0 0 0"/>
		<parent link="link0_passive"/>
		<child link="link1"/>
		<axis xyz="0 0 1"/>
	</joint>
	<joint name="q1_passive" type="fixed">
		<origin xyz="0.33 0 0" rpy="-1.5707963267948966 0 0"/>
		<parent link="link1"/>
		<child link="link1_passive"/>
	</joint>
	<link name="link1_passive">
		<visual>
			<origin xyz="0 0 0.25" rpy="0 0 0"/>
			<material name="blue"/>
			<geometry>
				<cylinder length="0.5" radius="0.05"/>
			</geometry>
		</visual>
	</link>
	<joint name="q1_x" type="fixed">
		<origin xyz="0 0 0" rpy="0 1.571 0"/>
		<parent link="link1_passive"/>
		<child link="link1_x_axis"/>
	</joint>
	<link name="link2"/>
	<link name="link2_x_axis">
		<visual>
			<origin xyz="0 0 0.25" rpy="0 0 0"/>
			<material name="red"/>
			<geometry>
				<cylinder length="0.5" radius="0.05"/>
			</geometry>
		</visual>
	</link>
	<joint name="q2" type="revolute">
		<origin xyz="0 0 0" rpy="0 0 0"/>
		<parent link="link1_passive"/>
		<child link="link2"/>
		<axis xyz="0 0 1"/>
	</joint>
	<joint name="q2_passive" type="fixed">
		<origin xyz="1.35 0 0" rpy="0 0 0"/>
		<parent link="link2"/>
		<child link="link2_passive"/>
	</joint>
	<link name="link2_passive">
		<visual>
			<origin xyz="0 0 0.25" rpy="0 0 0"/>
			<material name="blue"/>
			<geometry>
				<cylinder length="0.5" radius="0.05"/>
			</geometry>
		</visual>
	</link>
	<joint name="q2_x" type="fixed">
		<origin xyz="0 0 0" rpy="0 1.571 0"/>
		<parent link="link2_passive"/>
		<child link="link2_x_axis"/>
	</joint>
	<link name="link3"/>
	<link name="link3_x_axis">
		<visual>
			<origin xyz="0 0 0.25" rpy="0 0 0"/>
			<material name="red"/>
			<geometry>
				<cylinder length="0.5" radius="0.05"/>
			</geometry>
		</visual>
	</link>
	<joint name="q3" type="revolute">
		<origin xyz="0 0 0" rpy="0 0 0"/>
		<parent link="link2_passive"/>
		<child link="link3"/>
		<axis xyz="0 0 1"/>
	</joint>
	<joint name="q3_passive" type="fixed">
		<origin xyz="0.115 0 0" rpy="1.5707963267948966 0 0"/>
		<parent link="link3"/>
		<child link="link3_passive"/>
	</joint>
	<link name="link3_passive">
		<visual>
			<origin xyz="0 0 0.25" rpy="0 0 0"/>
			<material name="blue"/>
			<geometry>
				<cylinder length="0.5" radius="0.05"/>
			</geometry>
		</visual>
	</link>
	<joint name="q3_x" type="fixed">
		<origin xyz="0 0 0" rpy="0 1.571 0"/>
		<parent link="link3_passive"/>
		<child link="link3_x_axis"/>
	</joint>
	<link name="link4"/>
	<link name="link4_x_axis">
		<visual>
			<origin xyz="0 0 0.25" rpy="0 0 0"/>
			<material name="red"/>
			<geometry>
				<cylinder length="0.5" radius="0.05"/>
			</geometry>
		</visual>
	</link>
	<joint name="q4" type="revolute">
		<origin xyz="0 0 1.42" rpy="0 0 0"/>
		<parent link="link3_passive"/>
		<child link="link4"/>
		<axis xyz="0 0 1"/>
	</joint>
	<joint name="q4_passive" type="fixed">
		<origin xyz="0 0 0" rpy="-1.5707963267948966 0 0"/>
		<parent link="link4"/>
		<child link="link4_passive"/>
	</joint>
	<link name="link4_passive">
		<visual>
			<origin xyz="0 0 0.25" rpy="0 0 0"/>
			<material name="blue"/>
			<geometry>
				<cylinder length="0.5" radius="0.05"/>
			</geometry>
		</visual>
	</link>
	<joint name="q4_x" type="fixed">
		<origin xyz="0 0 0" rpy="0 1.571 0"/>
		<parent link="link4_passive"/>
		<child link="link4_x_axis"/>
	</joint>
	<link name="link5"/>
	<link name="link5_x_axis">
		<visual>
			<origin xyz="0 0 0.25" rpy="0 0 0"/>
			<material name="red"/>
			<geometry>
				<cylinder length="0.5" radius="0.05"/>
			</geometry>
		</visual>
	</link>
	<joint name="q5" type="revolute">
		<origin xyz="0 0 0" rpy="0 0 0"/>
		<parent link="link4_passive"/>
		<child link="link5"/>
		<axis xyz="0 0 1"/>
	</joint>
	<joint name="q5_passive" type="fixed">
		<origin xyz="0.215 0 0" rpy="1.5707963267948966 0 0"/>
		<parent link="link5"/>
		<child link="link5_passive"/>
	</joint>
	<link name="link5_passive">
		<visual>
			<origin xyz="0 0 0.25" rpy="0 0 0"/>
			<material name="blue"/>
			<geometry>
				<cylinder length="0.5" radius="0.05"/>
			</geometry>
		</visual>
	</link>
	<joint name="q5_x" type="fixed">
		<origin xyz="0 0 0" rpy="0 1.571 0"/>
		<parent link="link5_passive"/>
		<child link="link5_x_axis"/>
	</joint>
</robot>