<robot name="example_robot">
<!-- my sticks -->

<!-- Base -->
	<link name="base_black_cylinder">
		<visual>
			<origin xyz="0 0 0.2" rpy="0 0 0"/>
			<material name="black">
				<color rgba="0 0 0 1"/>
			</material>
			<geometry>
				<cylinder length="0.4" radius="0.5"/>
			</geometry>
		</visual>
	</link>
	<link name="base_box_on_back">
		<visual>
			<origin xyz="0 0 0.3" rpy="0 0 0"/>
			<material name="orange">
				<color rgba="1 0.35 0.045 1"/>
			</material>
			<geometry>
				<box size="0.5 0.5 0.6" />
			</geometry>
		</visual>
	</link>
	<link name="base_sticking_out_box">
		<visual>
			<origin xyz="0 0 0.1" rpy="0 0 0 "/>
			<material name="orange"/>
			<geometry>
				<box size="0.4 0.3 0.2" />
			</geometry>
		</visual>
	</link>
	<joint name="base_construction_joint_1" type="fixed">
		<origin xyz="0.15 -0.2 0.3" rpy="1.571 0 0"/>
		<parent link="base_box_on_back"/>
		<child link="base_black_cylinder"/>
	</joint>
	<joint name="base_construction_joint_2" type="fixed">
		<origin xyz="-0.45 -0.1 0" rpy="0 0 0"/>
		<parent link="base_sticking_out_box"/>
		<child link="base_box_on_back"/>

	</joint>
	
	<joint name="L2" type="fixed">
		<origin xyz="0 0 -0.3" rpy="0 0 0"/>
		<parent link="link1_passive"/>
		<child link="base_sticking_out_box"/>
	</joint>
	<!-- End base-->


	
<!-- My link 1-->
	<link name="cylinder_between_0_1">
		<visual>
			<origin xyz="0 0 0" rpy="0 0 0"/>
			<material name="orange">
				<color rgba="1 0.35 0.045 1"/>
             </material>
			<geometry>
				<cylinder length="0.3" radius="0.15"/>
			</geometry>
		</visual>
	</link>
	<link name="my_link1">
		<visual>
			<origin xyz="0 0 0.7" rpy="0 -1.571 0"/>
			<material name="orange"/>
			<geometry>
				<box size="0.15 0.15 1.4" />
			</geometry>
		</visual>
	</link>
	<link name="cylinder_between_1_2">
		<visual>
			<origin xyz="0 0 0" rpy="0 0 0"/>
			<material name="orange">
				<color rgba="1 0.35 0.045 1"/>
             </material>
			<geometry>
				<cylinder length="0.2" radius="0.15"/>
			</geometry>
		</visual>
	</link>	
	<joint name="my_link1_construction_joint_1" type="fixed">
		<origin xyz="-0.65 0 .7" rpy="0 0 0"/>
		<parent link="my_link1"/>
		<child link="cylinder_between_0_1"/>     
	</joint>
	<joint name="my_link1_construction_joint_2" type="fixed">
		<origin xyz="-0.7 0 -0.7" rpy="0 0 0"/>
		<parent link="cylinder_between_1_2"/>
		<child link="my_link1"/>     
	</joint>
	
	
	<joint name="L3" type="fixed">
		<origin xyz="0 0 0" rpy="0 0 0"/>
		<parent link="link2_passive"/>
		<child link="cylinder_between_1_2"/>
	</joint>
<!-- End my link 1-->

<!-- My link 2-->
	<link name="my_link2">
		<visual>
			<origin xyz="0 0 0.55" rpy="0 0 0"/>
			<material name="orange"/>
			<geometry>
				<cylinder length="1.1" radius="0.1"/>
			</geometry>
		</visual>
	</link>
	
	<link name="zwezenie">
		<visual>
			<origin xyz="0 0 0.1" rpy="0 0 0"/>
	     	<material name="orange">
				<color rgba="0.9 0.9 0.9 1.0"/>
			</material>
			<geometry>
				<cylinder length="0.3" radius="0.05"/>
			</geometry>
		</visual>
	</link>
	
	<joint name="my_link2_construction_joint_1" type="fixed">
		<origin xyz="0 0 1.1" rpy="0 0 0"/>
		<parent link="my_link2"/>
		<child link="zwezenie"/>
	</joint>
	
	<joint name="L4" type="fixed">
		<origin xyz="0 0 0" rpy="0 0 0"/>
		<parent link="link3_passive"/>
		<child link="my_link2"/>
	</joint>

<!-- End my link 2-->

	
	<!-- * * * Link 3 * * * -->	

	<link name="end_part_cylinder_w_poprzek">
		<visual>
			<origin xyz="0 0 0" rpy="0 0 0"/>
			<material name="orange">
				<color rgba="1 0.35 0.045 1"/>
             </material>
			<geometry>
				<cylinder length="0.25" radius="0.1"/>
			</geometry>
		</visual>
	</link>	


	
	<joint name="L5" type="fixed">
		<origin xyz="0 0 0" rpy="0 0 0"/>
		<parent link="link4_passive"/>
		<child link="end_part_cylinder_w_poprzek"/>
	</joint>
 
<!-- end part -->

	<link name="end_part_cylinder">
		<visual>
			<origin xyz="0 0 -0.06" rpy="0 0 0"/>
			<material name="orange"/>
			<geometry>
				<cylinder length="0.12" radius="0.1"/>
			</geometry>
		</visual>
	</link>
	<joint name="L6" type="fixed">
		<origin xyz="0 0 0" rpy="0 0 0"/>
		<parent link="link6_passive"/>
		<child link="end_part_cylinder"/>
	</joint>

<!-- end of my sticks -->


	<link name="link0_passive">
		<visual>
			<material name="blue">
				<color rgba="0 0 .8 1"/>
			</material>
			<geometry>
				<origin xyz="0 0 0" rpy="0 0 0"/>
				<cylinder length="0.0" radius="0.0"/>
			</geometry>
		</visual>
	</link>
	<link name="link0_x_axis">
		<visual>
			<material name="red">
				<color rgba="1 0 0 1"/>
			</material>
			<geometry>
				<origin xyz="0 0 0" rpy="0 0 0"/>
				<cylinder length="0.0" radius="0.0"/>
			</geometry>
		</visual>
	</link>
	<joint name="q0_x" type="fixed">
		<origin xyz="0 0 0" rpy="0 1.571 0"/>
		<parent link="link0_passive"/>
		<child link="link0_x_axis"/>
	</joint>
	<link name="link1"/>
	<link name="link1_x_axis">
		<visual>
			<origin xyz="0 0 0.25" rpy="0 0 0"/>
			<material name="red"/>
			<geometry>
				<cylinder length="0.5" radius="0.05"/>
			</geometry>
		</visual>
	</link>
	<joint name="q1" type="revolute"> 
		<origin xyz="0 0 0.645" rpy="0 0 0"/>
		<parent link="link0_passive"/>
		<child link="link1"/>
		<axis xyz="0 0 1"/>
	</joint>
	<joint name="q1_passive" type="fixed">
		<origin xyz="0.33 0 0" rpy="1.5707963267948966 0 0"/>
		<parent link="link1"/>
		<child link="link1_passive"/>
	</joint>
	<link name="link1_passive">
		<visual>
			<origin xyz="0 0 0.25" rpy="0 0 0"/>
			<material name="blue"/>
			<geometry>
				<cylinder length="0.5" radius="0.05"/>
			</geometry>
		</visual>
	</link>
	<joint name="q1_x" type="fixed">
		<origin xyz="0 0 0" rpy="0 1.571 0"/>
		<parent link="link1_passive"/>
		<child link="link1_x_axis"/>
	</joint>
	<link name="link2"/>
	<link name="link2_x_axis">
		<visual>
			<origin xyz="0 0 0.25" rpy="0 0 0"/>
			<material name="red"/>
			<geometry>
				<cylinder length="0.5" radius="0.05"/>
			</geometry>
		</visual>
	</link>
	<joint name="q2" type="revolute">
		<origin xyz="0 0 0" rpy="0 0 1.5707963267948966"/>
		<parent link="link1_passive"/>
		<child link="link2"/>
		<axis xyz="0 0 1"/>
	</joint>
	<joint name="q2_passive" type="fixed">
		<origin xyz="1.35 0 0" rpy="0 0 0"/>
		<parent link="link2"/>
		<child link="link2_passive"/>
	</joint>
	<link name="link2_passive">
		<visual>
			<origin xyz="0 0 0.25" rpy="0 0 0"/>
			<material name="blue"/>
			<geometry>
				<cylinder length="0.5" radius="0.05"/>
			</geometry>
		</visual>
	</link>
	<joint name="q2_x" type="fixed">
		<origin xyz="0 0 0" rpy="0 1.571 0"/>
		<parent link="link2_passive"/>
		<child link="link2_x_axis"/>
	</joint>
	<link name="link3"/>
	<link name="link3_x_axis">
		<visual>
			<origin xyz="0 0 0.25" rpy="0 0 0"/>
			<material name="red"/>
			<geometry>
				<cylinder length="0.5" radius="0.05"/>
			</geometry>
		</visual>
	</link>
	<joint name="q3" type="revolute">
		<origin xyz="0 0 0" rpy="0 0 0"/>
		<parent link="link2_passive"/>
		<child link="link3"/>
		<axis xyz="0 0 1"/>
	</joint>
	<joint name="q3_passive" type="fixed">
		<origin xyz="0.115 0 0" rpy="1.5707963267948966 0 0"/>
		<parent link="link3"/>
		<child link="link3_passive"/>
	</joint>
	<link name="link3_passive">
		<visual>
			<origin xyz="0 0 0.25" rpy="0 0 0"/>
			<material name="blue"/>
			<geometry>
				<cylinder length="0.5" radius="0.05"/>
			</geometry>
		</visual>
	</link>
	<joint name="q3_x" type="fixed">
		<origin xyz="0 0 0" rpy="0 1.571 0"/>
		<parent link="link3_passive"/>
		<child link="link3_x_axis"/>
	</joint>
	<link name="link4"/>
	<link name="link4_x_axis">
		<visual>
			<origin xyz="0 0 0.25" rpy="0 0 0"/>
			<material name="red"/>
			<geometry>
				<cylinder length="0.5" radius="0.05"/>
			</geometry>
		</visual>
	</link>
	<joint name="q4" type="revolute">
		<origin xyz="0 0 1.42" rpy="0 0 0"/>
		<parent link="link3_passive"/>
		<child link="link4"/>
		<axis xyz="0 0 1"/>
	</joint>
	<joint name="q4_passive" type="fixed">
		<origin xyz="0 0 0" rpy="-1.5707963267948966 0 0"/>
		<parent link="link4"/>
		<child link="link4_passive"/>
	</joint>
	<link name="link4_passive">
		<visual>
			<origin xyz="0 0 0.25" rpy="0 0 0"/>
			<material name="blue"/>
			<geometry>
				<cylinder length="0.5" radius="0.05"/>
			</geometry>
		</visual>
	</link>
	<joint name="q4_x" type="fixed">
		<origin xyz="0 0 0" rpy="0 1.571 0"/>
		<parent link="link4_passive"/>
		<child link="link4_x_axis"/>
	</joint>
	<link name="link5"/>
	<link name="link5_x_axis">
		<visual>
			<origin xyz="0 0 0.25" rpy="0 0 0"/>
			<material name="red"/>
			<geometry>
				<cylinder length="0.5" radius="0.05"/>
			</geometry>
		</visual>
	</link>
	<joint name="q5" type="revolute">
		<origin xyz="0 0 0" rpy="0 0 0"/>
		<parent link="link4_passive"/>
		<child link="link5"/>
		<axis xyz="0 0 1"/>
	</joint>
	<joint name="q5_passive" type="fixed">
		<origin xyz="0 0 0" rpy="1.5707963267948966 0 0"/>
		<parent link="link5"/>
		<child link="link5_passive"/>
	</joint>
	<link name="link5_passive">
		<visual>
			<origin xyz="0 0 0.25" rpy="0 0 0"/>
			<material name="blue"/>
			<geometry>
				<cylinder length="0.5" radius="0.05"/>
			</geometry>
		</visual>
	</link>
	<joint name="q5_x" type="fixed">
		<origin xyz="0 0 0" rpy="0 1.571 0"/>
		<parent link="link5_passive"/>
		<child link="link5_x_axis"/>
	</joint>
	<link name="link6"/>
	<link name="link6_x_axis">
		<visual>
			<origin xyz="0 0 0.25" rpy="0 0 0"/>
			<material name="red"/>
			<geometry>
				<cylinder length="0.5" radius="0.05"/>
			</geometry>
		</visual>
	</link>
	<joint name="q6" type="revolute">
		<origin xyz="0 0 0.215" rpy="0 0 0"/>
		<parent link="link5_passive"/>
		<child link="link6"/>
		<axis xyz="0 0 1"/>
	</joint>
	<joint name="q6_passive" type="fixed">
		<origin xyz="0 0 0" rpy="0 0 0"/>
		<parent link="link6"/>
		<child link="link6_passive"/>
	</joint>
	<link name="link6_passive">
		<visual>
			<origin xyz="0 0 0.25" rpy="0 0 0"/>
			<material name="blue"/>
			<geometry>
				<cylinder length="0.5" radius="0.05"/>
			</geometry>
		</visual>
	</link>
	<joint name="q6_x" type="fixed">
		<origin xyz="0 0 0" rpy="0 1.571 0"/>
		<parent link="link6_passive"/>
		<child link="link6_x_axis"/>
	</joint>
</robot>
